/usr/local/lib/python3.10/dist-packages/rasa/core/tracker_store.py:1044: MovedIn20Warning: Deprecated API features detected! These feature(s) are not compatible with SQLAlchemy 2.0. To prevent incompatible upgrades prior to updating applications, ensure requirements files are pinned to "sqlalchemy<2.0". Set environment variable SQLALCHEMY_WARN_20=1 to show all deprecation warnings.  Set environment variable SQLALCHEMY_SILENCE_UBER_WARNING=1 to silence this message. (Background on SQLAlchemy 2.0 at: https://sqlalche.me/e/b8d9)
  Base: DeclarativeMeta = declarative_base()
/usr/local/lib/python3.10/dist-packages/rasa/shared/utils/validation.py:134: DeprecationWarning: pkg_resources is deprecated as an API. See https://setuptools.pypa.io/en/latest/pkg_resources.html
  import pkg_resources
/usr/local/lib/python3.10/dist-packages/pkg_resources/__init__.py:3154: DeprecationWarning: Deprecated call to `pkg_resources.declare_namespace('google')`.
Implementing implicit namespace packages (as specified in PEP 420) is preferred to `pkg_resources.declare_namespace`. See https://setuptools.pypa.io/en/latest/references/keywords.html#keyword-namespace-packages
  declare_namespace(pkg)
/usr/local/lib/python3.10/dist-packages/pkg_resources/__init__.py:3154: DeprecationWarning: Deprecated call to `pkg_resources.declare_namespace('google.cloud')`.
Implementing implicit namespace packages (as specified in PEP 420) is preferred to `pkg_resources.declare_namespace`. See https://setuptools.pypa.io/en/latest/references/keywords.html#keyword-namespace-packages
  declare_namespace(pkg)
/usr/local/lib/python3.10/dist-packages/pkg_resources/__init__.py:3154: DeprecationWarning: Deprecated call to `pkg_resources.declare_namespace('mpl_toolkits')`.
Implementing implicit namespace packages (as specified in PEP 420) is preferred to `pkg_resources.declare_namespace`. See https://setuptools.pypa.io/en/latest/references/keywords.html#keyword-namespace-packages
  declare_namespace(pkg)
/usr/local/lib/python3.10/dist-packages/pkg_resources/__init__.py:3154: DeprecationWarning: Deprecated call to `pkg_resources.declare_namespace('ruamel')`.
Implementing implicit namespace packages (as specified in PEP 420) is preferred to `pkg_resources.declare_namespace`. See https://setuptools.pypa.io/en/latest/references/keywords.html#keyword-namespace-packages
  declare_namespace(pkg)
/usr/local/lib/python3.10/dist-packages/pkg_resources/__init__.py:3154: DeprecationWarning: Deprecated call to `pkg_resources.declare_namespace('sphinxcontrib')`.
Implementing implicit namespace packages (as specified in PEP 420) is preferred to `pkg_resources.declare_namespace`. See https://setuptools.pypa.io/en/latest/references/keywords.html#keyword-namespace-packages
  declare_namespace(pkg)
/usr/local/lib/python3.10/dist-packages/sanic_cors/extension.py:39: DeprecationWarning: distutils Version classes are deprecated. Use packaging.version instead.
  SANIC_VERSION = LooseVersion(sanic_version)
/usr/local/lib/python3.10/dist-packages/tensorflow/lite/python/util.py:52: DeprecationWarning: jax.xla_computation is deprecated. Please use the AOT APIs.
  from jax import xla_computation as _xla_computation
2024-11-03 13:25:45 INFO     numexpr.utils  - NumExpr defaulting to 2 threads.
2024-11-03 13:25:47 INFO     root  - Starting Rasa server on http://0.0.0.0:5005
2024-11-03 13:25:47 INFO     rasa.core.processor  - Loading model models/20241103-114041-rapid-spring.tar.gz...
2024-11-03 13:26:20 WARNING  rasa.shared.utils.common  - The UnexpecTED Intent Policy is currently experimental and might change or be removed in the future ðŸ”¬ Please share your feedback on it in the forum (https://forum.rasa.com) to help us make this feature ready for production.
2024-11-03 13:26:36 INFO     root  - Rasa server is up and running.
[2024-11-03 13:26:52 +0000] [29292] [ERROR] Exception occurred while handling uri: 'http://0a05-34-173-109-107.ngrok-free.app/webhooks/telegram/webhook'
Traceback (most recent call last):
  File "handle_request", line 83, in handle_request
    )
  File "/usr/local/lib/python3.10/dist-packages/rasa/core/channels/telegram.py", line 223, in message
    credentials = await out_channel.get_me()
  File "/usr/local/lib/python3.10/dist-packages/aiogram/bot/bot.py", line 215, in get_me
    result = await self.request(api.Methods.GET_ME, payload)
  File "/usr/local/lib/python3.10/dist-packages/aiogram/bot/base.py", line 208, in request
    return await api.make_request(self.session, self.server, self.__token, method, data, files,
  File "/usr/local/lib/python3.10/dist-packages/aiogram/bot/api.py", line 139, in make_request
    async with session.post(url, data=req, **kwargs) as response:
  File "/usr/local/lib/python3.10/dist-packages/aiohttp/client.py", line 1197, in __aenter__
    self._resp = await self._coro
  File "/usr/local/lib/python3.10/dist-packages/aiohttp/client.py", line 479, in _request
    handle = tm.start()
  File "/usr/local/lib/python3.10/dist-packages/aiohttp/helpers.py", line 660, in start
    return self._loop.call_at(when, self.__call__)
  File "uvloop/loop.pyx", line 1339, in uvloop.loop.Loop.call_at
  File "uvloop/loop.pyx", line 1315, in uvloop.loop.Loop.call_later
  File "uvloop/loop.pyx", line 705, in uvloop.loop.Loop._check_closed
RuntimeError: Event loop is closed
[2024-11-03 13:27:56 +0000] [29292] [ERROR] Exception occurred while handling uri: 'http://0a05-34-173-109-107.ngrok-free.app/webhooks/telegram/webhook'
Traceback (most recent call last):
  File "handle_request", line 83, in handle_request
    )
  File "/usr/local/lib/python3.10/dist-packages/rasa/core/channels/telegram.py", line 223, in message
    credentials = await out_channel.get_me()
  File "/usr/local/lib/python3.10/dist-packages/aiogram/bot/bot.py", line 215, in get_me
    result = await self.request(api.Methods.GET_ME, payload)
  File "/usr/local/lib/python3.10/dist-packages/aiogram/bot/base.py", line 208, in request
    return await api.make_request(self.session, self.server, self.__token, method, data, files,
  File "/usr/local/lib/python3.10/dist-packages/aiogram/bot/api.py", line 139, in make_request
    async with session.post(url, data=req, **kwargs) as response:
  File "/usr/local/lib/python3.10/dist-packages/aiohttp/client.py", line 1197, in __aenter__
    self._resp = await self._coro
  File "/usr/local/lib/python3.10/dist-packages/aiohttp/client.py", line 479, in _request
    handle = tm.start()
  File "/usr/local/lib/python3.10/dist-packages/aiohttp/helpers.py", line 660, in start
    return self._loop.call_at(when, self.__call__)
  File "uvloop/loop.pyx", line 1339, in uvloop.loop.Loop.call_at
  File "uvloop/loop.pyx", line 1315, in uvloop.loop.Loop.call_later
  File "uvloop/loop.pyx", line 705, in uvloop.loop.Loop._check_closed
RuntimeError: Event loop is closed
[2024-11-03 13:29:15 +0000] [29292] [ERROR] Exception occurred while handling uri: 'http://0a05-34-173-109-107.ngrok-free.app/webhooks/telegram/webhook'
Traceback (most recent call last):
  File "handle_request", line 83, in handle_request
    )
  File "/usr/local/lib/python3.10/dist-packages/rasa/core/channels/telegram.py", line 223, in message
    credentials = await out_channel.get_me()
  File "/usr/local/lib/python3.10/dist-packages/aiogram/bot/bot.py", line 215, in get_me
    result = await self.request(api.Methods.GET_ME, payload)
  File "/usr/local/lib/python3.10/dist-packages/aiogram/bot/base.py", line 208, in request
    return await api.make_request(self.session, self.server, self.__token, method, data, files,
  File "/usr/local/lib/python3.10/dist-packages/aiogram/bot/api.py", line 139, in make_request
    async with session.post(url, data=req, **kwargs) as response:
  File "/usr/local/lib/python3.10/dist-packages/aiohttp/client.py", line 1197, in __aenter__
    self._resp = await self._coro
  File "/usr/local/lib/python3.10/dist-packages/aiohttp/client.py", line 479, in _request
    handle = tm.start()
  File "/usr/local/lib/python3.10/dist-packages/aiohttp/helpers.py", line 660, in start
    return self._loop.call_at(when, self.__call__)
  File "uvloop/loop.pyx", line 1339, in uvloop.loop.Loop.call_at
  File "uvloop/loop.pyx", line 1315, in uvloop.loop.Loop.call_later
  File "uvloop/loop.pyx", line 705, in uvloop.loop.Loop._check_closed
RuntimeError: Event loop is closed
